<?xml version='1.0' encoding='utf-8'?>
<doc><id>504</id><url>https://docs.python.org/zh-cn/3/library/asyncio-exceptions.html</url><title>异常</title><body>源代码: Lib/asyncio/exceptions.py
该操作已超过规定的截止日期。
重要
这个异常与内置 TimeoutError 异常不同。
该操作已被取消。
取消asyncio任务时，可以捕获此异常以执行自定义操作。在几乎所有情况下，都必须重新引发异常。
在 3.8 版更改: CancelledError 现在是 BaseException 的子类。
Task 或 Future 的内部状态无效。
在为已设置结果值的未来对象设置结果值等情况下，可以引发此问题。
"sendfile" 系统调用不适用于给定的套接字或文件类型。
子类 RuntimeError 。
请求的读取操作未完全完成。
由 asyncio stream APIs 提出
此异常是 EOFError 的子类。
预期字节的总数（ int ）。
到达流结束之前读取的 bytes 字符串。
在查找分隔符时达到缓冲区大小限制。
由 asyncio stream APIs 提出
要消耗的字节总数。
队列集
事件循环
</body></doc>